2023-01-26 21:49:33.825 | INFO     | tools.basepage:wait_until_ele_visible:22 - 等待('xpath', '//input[@placeholder="用户名"]')可见
2023-01-26 21:49:33.825 | INFO     | tools.basepage:wait_until_ele_visible:28 - 等待匹配('xpath', '//input[@placeholder="用户名"]')的第一个元素可见。。。
2023-01-26 21:49:53.909 | ERROR    | tools.basepage:wait_until_ele_visible:31 - 等待失败！请确认元素定位是否正确，是否在运行过程中发生了改变，是否在iframe中
Traceback (most recent call last):

  File "C:\Users\jielin\PycharmProjects\Web_PO_V1\main.py", line 6, in <module>
    pytest.main([
    │      └ <function main at 0x0000021D03BCA170>
    └ <module 'pytest' from 'D:\\Python\\lib\\site-packages\\pytest\\__init__.py'>

  File "D:\Python\lib\site-packages\_pytest\config\__init__.py", line 164, in main
    ret: Union[ExitCode, int] = config.hook.pytest_cmdline_main(
         │     │                │      │    └ <_HookCaller 'pytest_cmdline_main'>
         │     │                │      └ <_pytest.config.compat.PathAwareHookProxy object at 0x0000021D059D5570>
         │     │                └ <_pytest.config.Config object at 0x0000021D059D53F0>
         │     └ <enum 'ExitCode'>
         └ typing.Union

  File "D:\Python\lib\site-packages\pluggy\_hooks.py", line 265, in __call__
    return self._hookexec(self.name, self.get_hookimpls(), kwargs, firstresult)
           │    │         │    │     │    │                │       └ True
           │    │         │    │     │    │                └ {'config': <_pytest.config.Config object at 0x0000021D059D53F0>}
           │    │         │    │     │    └ <function _HookCaller.get_hookimpls at 0x0000021D0386ECB0>
           │    │         │    │     └ <_HookCaller 'pytest_cmdline_main'>
           │    │         │    └ 'pytest_cmdline_main'
           │    │         └ <_HookCaller 'pytest_cmdline_main'>
           │    └ <bound method PluginManager._hookexec of <_pytest.config.PytestPluginManager object at 0x0000021D03156800>>
           └ <_HookCaller 'pytest_cmdline_main'>

  File "D:\Python\lib\site-packages\pluggy\_manager.py", line 80, in _hookexec
    return self._inner_hookexec(hook_name, methods, kwargs, firstresult)
           │    │               │          │        │       └ True
           │    │               │          │        └ {'config': <_pytest.config.Config object at 0x0000021D059D53F0>}
           │    │               │          └ [<HookImpl plugin_name='main', plugin=<module '_pytest.main' from 'D:\\Python\\lib\\site-packages\\_pytest\\main.py'>>, <Hook...
           │    │               └ 'pytest_cmdline_main'
           │    └ <function _multicall at 0x0000021D0386DBD0>
           └ <_pytest.config.PytestPluginManager object at 0x0000021D03156800>

  File "D:\Python\lib\site-packages\pluggy\_callers.py", line 39, in _multicall
    res = hook_impl.function(*args)
          │         │         └ [<_pytest.config.Config object at 0x0000021D059D53F0>]
          │         └ <function pytest_cmdline_main at 0x0000021D03C07EB0>
          └ <HookImpl plugin_name='main', plugin=<module '_pytest.main' from 'D:\\Python\\lib\\site-packages\\_pytest\\main.py'>>

  File "D:\Python\lib\site-packages\_pytest\main.py", line 315, in pytest_cmdline_main
    return wrap_session(config, _main)
           │            │       └ <function _main at 0x0000021D03C07F40>
           │            └ <_pytest.config.Config object at 0x0000021D059D53F0>
           └ <function wrap_session at 0x0000021D03C07E20>

  File "D:\Python\lib\site-packages\_pytest\main.py", line 268, in wrap_session
    session.exitstatus = doit(config, session) or 0
    │       │            │    │       └ <Session Web_PO_V1 exitstatus=<ExitCode.OK: 0> testsfailed=1 testscollected=11>
    │       │            │    └ <_pytest.config.Config object at 0x0000021D059D53F0>
    │       │            └ <function _main at 0x0000021D03C07F40>
    │       └ <ExitCode.OK: 0>
    └ <Session Web_PO_V1 exitstatus=<ExitCode.OK: 0> testsfailed=1 testscollected=11>

  File "D:\Python\lib\site-packages\_pytest\main.py", line 322, in _main
    config.hook.pytest_runtestloop(session=session)
    │      │    │                          └ <Session Web_PO_V1 exitstatus=<ExitCode.OK: 0> testsfailed=1 testscollected=11>
    │      │    └ <_HookCaller 'pytest_runtestloop'>
    │      └ <_pytest.config.compat.PathAwareHookProxy object at 0x0000021D059D5570>
    └ <_pytest.config.Config object at 0x0000021D059D53F0>

  File "D:\Python\lib\site-packages\pluggy\_hooks.py", line 265, in __call__
    return self._hookexec(self.name, self.get_hookimpls(), kwargs, firstresult)
           │    │         │    │     │    │                │       └ True
           │    │         │    │     │    │                └ {'session': <Session Web_PO_V1 exitstatus=<ExitCode.OK: 0> testsfailed=1 testscollected=11>}
           │    │         │    │     │    └ <function _HookCaller.get_hookimpls at 0x0000021D0386ECB0>
           │    │         │    │     └ <_HookCaller 'pytest_runtestloop'>
           │    │         │    └ 'pytest_runtestloop'
           │    │         └ <_HookCaller 'pytest_runtestloop'>
           │    └ <bound method PluginManager._hookexec of <_pytest.config.PytestPluginManager object at 0x0000021D03156800>>
           └ <_HookCaller 'pytest_runtestloop'>

  File "D:\Python\lib\site-packages\pluggy\_manager.py", line 80, in _hookexec
    return self._inner_hookexec(hook_name, methods, kwargs, firstresult)
           │    │               │          │        │       └ True
           │    │               │          │        └ {'session': <Session Web_PO_V1 exitstatus=<ExitCode.OK: 0> testsfailed=1 testscollected=11>}
           │    │               │          └ [<HookImpl plugin_name='main', plugin=<module '_pytest.main' from 'D:\\Python\\lib\\site-packages\\_pytest\\main.py'>>, <Hook...
           │    │               └ 'pytest_runtestloop'
           │    └ <function _multicall at 0x0000021D0386DBD0>
           └ <_pytest.config.PytestPluginManager object at 0x0000021D03156800>

  File "D:\Python\lib\site-packages\pluggy\_callers.py", line 39, in _multicall
    res = hook_impl.function(*args)
          │         │         └ [<Session Web_PO_V1 exitstatus=<ExitCode.OK: 0> testsfailed=1 testscollected=11>]
          │         └ <function pytest_runtestloop at 0x0000021D03C940D0>
          └ <HookImpl plugin_name='main', plugin=<module '_pytest.main' from 'D:\\Python\\lib\\site-packages\\_pytest\\main.py'>>

  File "D:\Python\lib\site-packages\_pytest\main.py", line 347, in pytest_runtestloop
    item.config.hook.pytest_runtest_protocol(item=item, nextitem=nextitem)
    │    │                                        │              └ <Function test_login_success>
    │    │                                        └ <Function test_login_failed[case2]>
    │    └ <member 'config' of 'Node' objects>
    └ <Function test_login_failed[case2]>

  File "D:\Python\lib\site-packages\pluggy\_hooks.py", line 265, in __call__
    return self._hookexec(self.name, self.get_hookimpls(), kwargs, firstresult)
           │    │         │    │     │    │                │       └ True
           │    │         │    │     │    │                └ {'item': <Function test_login_failed[case2]>, 'nextitem': <Function test_login_success>}
           │    │         │    │     │    └ <function _HookCaller.get_hookimpls at 0x0000021D0386ECB0>
           │    │         │    │     └ <_HookCaller 'pytest_runtest_protocol'>
           │    │         │    └ 'pytest_runtest_protocol'
           │    │         └ <_HookCaller 'pytest_runtest_protocol'>
           │    └ <bound method PluginManager._hookexec of <_pytest.config.PytestPluginManager object at 0x0000021D03156800>>
           └ <_HookCaller 'pytest_runtest_protocol'>

  File "D:\Python\lib\site-packages\pluggy\_manager.py", line 80, in _hookexec
    return self._inner_hookexec(hook_name, methods, kwargs, firstresult)
           │    │               │          │        │       └ True
           │    │               │          │        └ {'item': <Function test_login_failed[case2]>, 'nextitem': <Function test_login_success>}
           │    │               │          └ [<HookImpl plugin_name='runner', plugin=<module '_pytest.runner' from 'D:\\Python\\lib\\site-packages\\_pytest\\runner.py'>>,...
           │    │               └ 'pytest_runtest_protocol'
           │    └ <function _multicall at 0x0000021D0386DBD0>
           └ <_pytest.config.PytestPluginManager object at 0x0000021D03156800>

  File "D:\Python\lib\site-packages\pluggy\_callers.py", line 39, in _multicall
    res = hook_impl.function(*args)
          │         │         └ [<Function test_login_failed[case2]>, <Function test_login_success>]
          │         └ <function pytest_runtest_protocol at 0x0000021D03C06C20>
          └ <HookImpl plugin_name='runner', plugin=<module '_pytest.runner' from 'D:\\Python\\lib\\site-packages\\_pytest\\runner.py'>>

  File "D:\Python\lib\site-packages\_pytest\runner.py", line 111, in pytest_runtest_protocol
    runtestprotocol(item, nextitem=nextitem)
    │               │              └ <Function test_login_success>
    │               └ <Function test_login_failed[case2]>
    └ <function runtestprotocol at 0x0000021D03C06CB0>

  File "D:\Python\lib\site-packages\_pytest\runner.py", line 130, in runtestprotocol
    reports.append(call_and_report(item, "call", log))
    │       │      │               │             └ True
    │       │      │               └ <Function test_login_failed[case2]>
    │       │      └ <function call_and_report at 0x0000021D03C070A0>
    │       └ <method 'append' of 'list' objects>
    └ [<TestReport 'testcase/test_admin_login.py::TestLogin::test_login_failed[case2]' when='setup' outcome='passed'>]

  File "D:\Python\lib\site-packages\_pytest\runner.py", line 219, in call_and_report
    call = call_runtest_hook(item, when, **kwds)
           │                 │     │       └ {}
           │                 │     └ 'call'
           │                 └ <Function test_login_failed[case2]>
           └ <function call_runtest_hook at 0x0000021D03C071C0>

  File "D:\Python\lib\site-packages\_pytest\runner.py", line 258, in call_runtest_hook
    return CallInfo.from_call(
           │        └ <classmethod(<function CallInfo.from_call at 0x0000021D03C07490>)>
           └ <class '_pytest.runner.CallInfo'>

  File "D:\Python\lib\site-packages\_pytest\runner.py", line 338, in from_call
    result: Optional[TResult] = func()
            │        │          └ <function call_runtest_hook.<locals>.<lambda> at 0x0000021D074B2290>
            │        └ +TResult
            └ typing.Optional

  File "D:\Python\lib\site-packages\_pytest\runner.py", line 259, in <lambda>
    lambda: ihook(item=item, **kwds), when=when, reraise=reraise
            │          │       └ {}
            │          └ <Function test_login_failed[case2]>
            └ <_HookCaller 'pytest_runtest_call'>

  File "D:\Python\lib\site-packages\pluggy\_hooks.py", line 265, in __call__
    return self._hookexec(self.name, self.get_hookimpls(), kwargs, firstresult)
           │    │         │    │     │    │                │       └ False
           │    │         │    │     │    │                └ {'item': <Function test_login_failed[case2]>}
           │    │         │    │     │    └ <function _HookCaller.get_hookimpls at 0x0000021D0386ECB0>
           │    │         │    │     └ <_HookCaller 'pytest_runtest_call'>
           │    │         │    └ 'pytest_runtest_call'
           │    │         └ <_HookCaller 'pytest_runtest_call'>
           │    └ <bound method PluginManager._hookexec of <_pytest.config.PytestPluginManager object at 0x0000021D03156800>>
           └ <_HookCaller 'pytest_runtest_call'>

  File "D:\Python\lib\site-packages\pluggy\_manager.py", line 80, in _hookexec
    return self._inner_hookexec(hook_name, methods, kwargs, firstresult)
           │    │               │          │        │       └ False
           │    │               │          │        └ {'item': <Function test_login_failed[case2]>}
           │    │               │          └ [<HookImpl plugin_name='runner', plugin=<module '_pytest.runner' from 'D:\\Python\\lib\\site-packages\\_pytest\\runner.py'>>,...
           │    │               └ 'pytest_runtest_call'
           │    └ <function _multicall at 0x0000021D0386DBD0>
           └ <_pytest.config.PytestPluginManager object at 0x0000021D03156800>

  File "D:\Python\lib\site-packages\pluggy\_callers.py", line 39, in _multicall
    res = hook_impl.function(*args)
          │         │         └ [<Function test_login_failed[case2]>]
          │         └ <function pytest_runtest_call at 0x0000021D03C06E60>
          └ <HookImpl plugin_name='runner', plugin=<module '_pytest.runner' from 'D:\\Python\\lib\\site-packages\\_pytest\\runner.py'>>

  File "D:\Python\lib\site-packages\_pytest\runner.py", line 166, in pytest_runtest_call
    item.runtest()
    │    └ <function Function.runtest at 0x0000021D03D0D090>
    └ <Function test_login_failed[case2]>

  File "D:\Python\lib\site-packages\_pytest\python.py", line 1761, in runtest
    self.ihook.pytest_pyfunc_call(pyfuncitem=self)
    │    │                                   └ <Function test_login_failed[case2]>
    │    └ <property object at 0x0000021D03C2D4E0>
    └ <Function test_login_failed[case2]>

  File "D:\Python\lib\site-packages\pluggy\_hooks.py", line 265, in __call__
    return self._hookexec(self.name, self.get_hookimpls(), kwargs, firstresult)
           │    │         │    │     │    │                │       └ True
           │    │         │    │     │    │                └ {'pyfuncitem': <Function test_login_failed[case2]>}
           │    │         │    │     │    └ <function _HookCaller.get_hookimpls at 0x0000021D0386ECB0>
           │    │         │    │     └ <_HookCaller 'pytest_pyfunc_call'>
           │    │         │    └ 'pytest_pyfunc_call'
           │    │         └ <_HookCaller 'pytest_pyfunc_call'>
           │    └ <bound method PluginManager._hookexec of <_pytest.config.PytestPluginManager object at 0x0000021D03156800>>
           └ <_HookCaller 'pytest_pyfunc_call'>

  File "D:\Python\lib\site-packages\pluggy\_manager.py", line 80, in _hookexec
    return self._inner_hookexec(hook_name, methods, kwargs, firstresult)
           │    │               │          │        │       └ True
           │    │               │          │        └ {'pyfuncitem': <Function test_login_failed[case2]>}
           │    │               │          └ [<HookImpl plugin_name='python', plugin=<module '_pytest.python' from 'D:\\Python\\lib\\site-packages\\_pytest\\python.py'>>]
           │    │               └ 'pytest_pyfunc_call'
           │    └ <function _multicall at 0x0000021D0386DBD0>
           └ <_pytest.config.PytestPluginManager object at 0x0000021D03156800>

  File "D:\Python\lib\site-packages\pluggy\_callers.py", line 39, in _multicall
    res = hook_impl.function(*args)
          │         │         └ [<Function test_login_failed[case2]>]
          │         └ <function pytest_pyfunc_call at 0x0000021D03CDD6C0>
          └ <HookImpl plugin_name='python', plugin=<module '_pytest.python' from 'D:\\Python\\lib\\site-packages\\_pytest\\python.py'>>

  File "D:\Python\lib\site-packages\_pytest\python.py", line 192, in pytest_pyfunc_call
    result = testfunction(**testargs)
             │              └ {'admin_manage_driver': <selenium.webdriver.chrome.webdriver.WebDriver (session="c22057c828b17a55e9e7a1d3c53deb06")>, 'case':...
             └ <bound method TestLogin.test_login_failed of <testcase.test_admin_login.TestLogin object at 0x0000021D070A9B70>>

  File "C:\Users\jielin\PycharmProjects\Web_PO_V1\testcase\test_admin_login.py", line 38, in test_login_failed
    LoginPage(driver).login(case.get("user"), case.get("passwd"), case.get("code"))
    │         │             │    │            │    │              │    └ <method 'get' of 'dict' objects>
    │         │             │    │            │    │              └ {'title': '验证码错误', 'user': 'student', 'passwd': '123456a', 'code': 'lemon123', 'check': '验证码有误或已过期'}
    │         │             │    │            │    └ <method 'get' of 'dict' objects>
    │         │             │    │            └ {'title': '验证码错误', 'user': 'student', 'passwd': '123456a', 'code': 'lemon123', 'check': '验证码有误或已过期'}
    │         │             │    └ <method 'get' of 'dict' objects>
    │         │             └ {'title': '验证码错误', 'user': 'student', 'passwd': '123456a', 'code': 'lemon123', 'check': '验证码有误或已过期'}
    │         └ <selenium.webdriver.chrome.webdriver.WebDriver (session="c22057c828b17a55e9e7a1d3c53deb06")>
    └ <class 'pageobject.admin_manager.login_page.LoginPage'>

  File "C:\Users\jielin\PycharmProjects\Web_PO_V1\pageobject\admin_manager\login_page.py", line 39, in login
    self.input_text(self.user_input,"登录页面_输入用户名",user)
    │    │          │    │                       └ 'student'
    │    │          │    └ ('xpath', '//input[@placeholder="用户名"]')
    │    │          └ <pageobject.admin_manager.login_page.LoginPage object at 0x0000021D0759FC70>
    │    └ <function BasePage.input_text at 0x0000021D06FFDF30>
    └ <pageobject.admin_manager.login_page.LoginPage object at 0x0000021D0759FC70>

  File "C:\Users\jielin\PycharmProjects\Web_PO_V1\tools\basepage.py", line 89, in input_text
    ele = self.wait_until_ele_visible(locator, page_step)
          │    │                      │        └ '登录页面_输入用户名'
          │    │                      └ ('xpath', '//input[@placeholder="用户名"]')
          │    └ <function BasePage.wait_until_ele_visible at 0x0000021D06FFD2D0>
          └ <pageobject.admin_manager.login_page.LoginPage object at 0x0000021D0759FC70>

> File "C:\Users\jielin\PycharmProjects\Web_PO_V1\tools\basepage.py", line 29, in wait_until_ele_visible
    ele = self.wait.until(EC.visibility_of_element_located(locs))
          │    │    │     │  │                             └ ('xpath', '//input[@placeholder="用户名"]')
          │    │    │     │  └ <function visibility_of_element_located at 0x0000021D062EA7A0>
          │    │    │     └ <module 'selenium.webdriver.support.expected_conditions' from 'D:\\Python\\lib\\site-packages\\selenium\\webdriver\\support\\...
          │    │    └ <function WebDriverWait.until at 0x0000021D062EA290>
          │    └ <selenium.webdriver.support.wait.WebDriverWait (session="c22057c828b17a55e9e7a1d3c53deb06")>
          └ <pageobject.admin_manager.login_page.LoginPage object at 0x0000021D0759FC70>

  File "D:\Python\lib\site-packages\selenium\webdriver\support\wait.py", line 90, in until
    raise TimeoutException(message, screen, stacktrace)
          │                │        │       └ None
          │                │        └ None
          │                └ ''
          └ <class 'selenium.common.exceptions.TimeoutException'>

selenium.common.exceptions.TimeoutException: Message: 

2023-01-26 21:49:54.117 | INFO     | tools.basepage:save_page_shot:43 - 将页面截图保存至：C:\Users\jielin\PycharmProjects\Web_PO_V1\outputs\page_shots\登录页面_输入用户名_20230126_214953.png
